Workbook

Sheet Mufrodat
A1: Mufrodat Maret - April 2026
A3: Nomor | B3: Bahasa Indonesia | C3: Bahasa Arab Putra | D3: Bahasa Arab Putri | E3: Pagi
A4: 1 | B4: Jangan makan pakai tangan kiri | C4: لَا تَأْكُلْ بِيَدِكَ الْيُسْرَى | D4: لَا تَأْكُلِي بِيَدِكِ الْيُسْرَى | E4: 1
B5: Kamu jahat, tidak mau bantuin aku | C5: أَنْتَ شِرِّيرٌ، لَا تُرِيدُ أَنْ تُسَاعِدَنِي | D5: أَنْتِ شِرِّيرَةٌ، لَا تُرِيدِينَ أَنْ تُسَاعِدِينَنِي | E5: =E4+1 -> 2
B6: Makan lah pakai piring | C6: كُلْ فِي الصَّحْنِ | D6: كُلِي فِي الصَّحْنِ | E6: =E5+1 -> 3
B7: Kepalaku pusing bah | C7: رَأْسِي يُؤْلِمُنِي | D7: رَأْسِي يُؤْلِمُنِي | E7: =E6+1 -> 4
B8: Cepetin bagi makanannya | C8: أَسْرِعْ فِي تَوْزِيعِ الطَّعَامِ | D8: أَسْرِعِي فِي تَوْزِيعِ الطَّعَامِ | E8: =E7+1 -> 5
A9: 2 | B9: Apa lauknya? | C9: مَا الْإِدَامُ؟ | D9: مَا الْإِدَامُ؟ | E9: =E8+1 -> 6
B10: Cepetin sudah ada akhwatnya / ikhwannya | C10: أَسْرِعْ، فَقَدْ جَاءَتِ الْأَخَوَاتُ | D10: أَسْرِعِي، فَقَدْ جَاءَ الْإِخْوَانُ | E10: =E9+1 -> 7
B11: Siapa yang piket sapu? | C11: مَنْ حَارِسُ الْمَطْعَمِ؟ | D11: مَنْ حَارِسَةُ الْمَطْعَمِ؟ | E11: =E10+1 -> 8
B12: Hijabnya pindah situ | C12: اُنْقُلِ الْحِجَابَ إِلَى هُنَاكَ | D12: اُنْقُلِي الْحِجَابَ إِلَى هُنَاكِ | E12: =E11+1 -> 9
B13: Ah, fresh meat | C13: آهِ، لَحْمٌ طَازَجٌ | D13: آهِ، لَحْمٌ طَازَجٌ | E13: =E12+1 -> 10
A14: 3 | B14: Kekurangan konsumsi | C14: الطَّعَامُ نَاقِصٌ | D14: الطَّعَامُ نَاقِصٌ | E14: =E13+1 -> 11
B15: Jatahku mana? | C15: أَيْنَ حِصَّتِي؟ | D15: أَيْنَ حِصَّتِي؟ | E15: =E14+1 -> 12
B16: Makan apa? | C16: مَاذَا نَأْكُلُ؟ | D16: مَاذَا نَأْكُلُ؟ | E16: =E15+1 -> 13
B17: Ambil aja jatahku | C17: خُذْ حِصَّتِي | D17: خُذِي حِصَّتِي | E17: =E16+1 -> 14
B18: Mana sendok nasi? | C18: أَيْنَ مِلْعَقَةُ الْأَرُزِّ؟ | D18: أَيْنَ مِلْعَقَةُ الْأَرُزِّ؟ | E18: =E17+1 -> 15
A19: 4 | B19: Kamu nggak makan? | C19: أَلَا تَأْكُلُ؟ | D19: أَلَا تَأْكُلِينَ؟ | E19: =E18+1 -> 16
B20: Siapa yang ambil makan? | C20: مَنْ أَخَذَ الطَّعَامَ؟ | D20: مَنْ أَخَذَ الطَّعَامَ؟ | E20: =E19+1 -> 17
B21: Makannya sudah datang | C21: جَاءَ الطَّعَامُ | D21: جَاءَ الطَّعَامُ | E21: =E20+1 -> 18
B22: Siapa belum makan? | C22: مَنْ لَمْ يَأْكُلْ؟ | D22: مَنْ لَمْ تَأْكُلْ؟ | E22: =E21+1 -> 19
B23: Makan di mana? | C23: أَيْنَ نَأْكُلُ؟ | D23: أَيْنَ نَأْكُلُ؟ | E23: =E22+1 -> 20
A24: 5 | B24: Tolong ambilkan ikan lele aku | C24: مِنْ فَضْلِكَ خُذْ لِي سَمَكَ السِّلُّورِ | D24: مِنْ فَضْلِكِ خُذِي لِي سَمَكَ السِّلُّورِ | E24: =E23+1 -> 21
B25: Aku mau makan | C25: أُرِيدُ أَنْ آكُلَ | D25: أُرِيدُ أَنْ آكُلَ | E25: =E24+1 -> 22
B26: Siapa yang mau makananku? | C26: مَنْ يُرِيدُ طَعَامِي؟ | D26: مَنْ تُرِيدُ طَعَامِي؟ | E26: =E25+1 -> 23
B27: Lantainya licin | C27: الْأَرْضُ زَلِقَةٌ | D27: الْأَرْضُ زَلِقَةٌ | E27: =E26+1 -> 24
B28: Ada sambal kah? | C28: هَلْ تُوجَدُ شَطَّةٌ؟ | D28: هَلْ تُوجَدُ شَطَّةٌ؟ | E28: =E27+1 -> 25
A29: 6 | B29: Enak betul | C29: لَذِيذٌ جِدًّا | D29: لَذِيذٌ جِدًّا | E29: =E28+1 -> 26
B30: Makan kok masih hamburan | C30: لِمَاذَا الطَّعَامُ مُتَنَاثِرٌ هَكَذَا؟ | D30: لِمَاذَا الطَّعَامُ مُتَنَاثِرٌ هَكَذَا؟ | E30: =E29+1 -> 27
B31: Tinggal makan berisik betul | C31: الْأَكْلُ فَقَطْ وَمَعَ ذَلِكَ الضَّجِيجُ كَثِيرٌ | D31: الْأَكْلُ فَقَطْ وَمَعَ ذَلِكَ الضَّجِيجُ كَثِيرٌ | E31: =E30+1 -> 28
B32: Awas kepleset | C32: اِنْتَبِهْ لَا تَنْزَلِقْ | D32: اِنْتَبِهِي لَا تَنْزَلِقِي | E32: =E31+1 -> 29
B33: Bagi yang rata | C33: اِقْسِمْ بِالتَّسَاوِي | D33: اِقْسِمِي بِالتَّسَاوِي | E33: =E32+1 -> 30
A34: 7 | B34: Lauknya basi | C34: الْإِدَامُ فَاسِدٌ | D34: الْإِدَامُ فَاسِدٌ | E34: =E33+1 -> 31
B35: Nasinya habis | C35: نَفِدَ الْأَرُزُّ | D35: نَفِدَ الْأَرُزُّ
B36: Centongnya tenggelam di bawah nasi | C36: مِغْرَفَةُ الْأَرُزِّ غَارِقَةٌ تَحْتَ الْأَرُزِّ | D36: مِغْرَفَةُ الْأَرُزِّ غَارِقَةٌ تَحْتَ الْأَرُزِّ
B37: Siapa yang nggak makan sayur? | C37: مَنْ لَا يَأْكُلُ الْخُضَارَ؟ | D37: مَنْ لَا تَأْكُلُ الْخُضَارَ؟
B38: Nasinya belum matang | C38: الْأَرُزُّ لَمْ يَنْضُجْ بَعْدُ | D38: الْأَرُزُّ لَمْ يَنْضُجْ بَعْدُ
A39: 8 | B39: Jangan lama-lama ngambil nasinya | C39: لَا تُطِلْ فِي أَخْذِ الْأَرُزِّ | D39: لَا تُطِيلِي فِي أَخْذِ الْأَرُزِّ
B40: Awas licin, baru dipel | C40: اِنْتَبِهْ، الْأَرْضُ مَبْلُولَةٌ حَدِيثًا | D40: اِنْتَبِهِي، الْأَرْضُ مَبْلُولَةٌ حَدِيثًا
B41: Sendok nasinya masuk parit | C41: مِلْعَقَةُ الْأَرُزِّ سَقَطَتْ فِي الْمَجْرَى | D41: مِلْعَقَةُ الْأَرُزِّ سَقَطَتْ فِي الْمَجْرَى
...

Sheet Mufrodat Putra
A1: Mufrodat Maret - April 2026
A3: Nomor | B3: Bahasa Indonesia | C3: Bahasa Arab Putra | D3: Pagi
A4: 1 | B4: =Mufrodat!B4 -> Jangan makan pakai tangan kiri | C4: =Mufrodat!C4 -> لَا تَأْكُلْ بِيَدِكَ الْيُسْرَى | D4: 1
B5: =Mufrodat!B5 -> Kamu jahat, tidak mau bantuin aku | C5: =Mufrodat!C5 -> أَنْتَ شِرِّيرٌ، لَا تُرِيدُ أَنْ تُسَاعِدَنِي | D5: =D4+1 -> 2
B6: =Mufrodat!B6 -> Makan lah pakai piring | C6: =Mufrodat!C6 -> كُلْ فِي الصَّحْنِ | D6: =D5+1 -> 3
B7: =Mufrodat!B7 -> Kepalaku pusing bah | C7: =Mufrodat!C7 -> رَأْسِي يُؤْلِمُنِي | D7: =D6+1 -> 4
B8: =Mufrodat!B8 -> Cepetin bagi makanannya | C8: =Mufrodat!C8 -> أَسْرِعْ فِي تَوْزِيعِ الطَّعَامِ | D8: =D7+1 -> 5
A9: 2 | B9: =Mufrodat!B9 -> Apa lauknya? | C9: =Mufrodat!C9 -> مَا الْإِدَامُ؟ | D9: =D8+1 -> 6
B10: =Mufrodat!B10 -> Cepetin sudah ada akhwatnya / ikhwannya | C10: =Mufrodat!C10 -> أَسْرِعْ، فَقَدْ جَاءَتِ الْأَخَوَاتُ | D10: =D9+1 -> 7
B11: =Mufrodat!B11 -> Siapa yang piket sapu? | C11: =Mufrodat!C11 -> مَنْ حَارِسُ الْمَطْعَمِ؟ | D11: =D10+1 -> 8
B12: =Mufrodat!B12 -> Hijabnya pindah situ | C12: =Mufrodat!C12 -> اُنْقُلِ الْحِجَابَ إِلَى هُنَاكَ | D12: =D11+1 -> 9
B13: =Mufrodat!B13 -> Ah, fresh meat | C13: =Mufrodat!C13 -> آهِ، لَحْمٌ طَازَجٌ | D13: =D12+1 -> 10
A14: 3 | B14: =Mufrodat!B14 -> Kekurangan konsumsi | C14: =Mufrodat!C14 -> الطَّعَامُ نَاقِصٌ | D14: =D13+1 -> 11
B15: =Mufrodat!B15 -> Jatahku mana? | C15: =Mufrodat!C15 -> أَيْنَ حِصَّتِي؟ | D15: =D14+1 -> 12
B16: =Mufrodat!B16 -> Makan apa? | C16: =Mufrodat!C16 -> مَاذَا نَأْكُلُ؟ | D16: =D15+1 -> 13
B17: =Mufrodat!B17 -> Ambil aja jatahku | C17: =Mufrodat!C17 -> خُذْ حِصَّتِي | D17: =D16+1 -> 14
B18: =Mufrodat!B18 -> Mana sendok nasi? | C18: =Mufrodat!C18 -> أَيْنَ مِلْعَقَةُ الْأَرُزِّ؟ | D18: =D17+1 -> 15
A19: 4 | B19: =Mufrodat!B19 -> Kamu nggak makan? | C19: =Mufrodat!C19 -> أَلَا تَأْكُلُ؟ | D19: =D18+1 -> 16
B20: =Mufrodat!B20 -> Siapa yang ambil makan? | C20: =Mufrodat!C20 -> مَنْ أَخَذَ الطَّعَامَ؟ | D20: =D19+1 -> 17
B21: =Mufrodat!B21 -> Makannya sudah datang | C21: =Mufrodat!C21 -> جَاءَ الطَّعَامُ | D21: =D20+1 -> 18
B22: =Mufrodat!B22 -> Siapa belum makan? | C22: =Mufrodat!C22 -> مَنْ لَمْ يَأْكُلْ؟ | D22: =D21+1 -> 19
B23: =Mufrodat!B23 -> Makan di mana? | C23: =Mufrodat!C23 -> أَيْنَ نَأْكُلُ؟ | D23: =D22+1 -> 20
A24: 5 | B24: =Mufrodat!B24 -> Tolong ambilkan ikan lele aku | C24: =Mufrodat!C24 -> مِنْ فَضْلِكَ خُذْ لِي سَمَكَ السِّلُّورِ | D24: =D23+1 -> 21
B25: =Mufrodat!B25 -> Aku mau makan | C25: =Mufrodat!C25 -> أُرِيدُ أَنْ آكُلَ | D25: =D24+1 -> 22
B26: =Mufrodat!B26 -> Siapa yang mau makananku? | C26: =Mufrodat!C26 -> مَنْ يُرِيدُ طَعَامِي؟ | D26: =D25+1 -> 23
B27: =Mufrodat!B27 -> Lantainya licin | C27: =Mufrodat!C27 -> الْأَرْضُ زَلِقَةٌ | D27: =D26+1 -> 24
B28: =Mufrodat!B28 -> Ada sambal kah? | C28: =Mufrodat!C28 -> هَلْ تُوجَدُ شَطَّةٌ؟ | D28: =D27+1 -> 25
A29: 6 | B29: =Mufrodat!B29 -> Enak betul | C29: =Mufrodat!C29 -> لَذِيذٌ جِدًّا | D29: =D28+1 -> 26
B30: =Mufrodat!B30 -> Makan kok masih hamburan | C30: =Mufrodat!C30 -> لِمَاذَا الطَّعَامُ مُتَنَاثِرٌ هَكَذَا؟ | D30: =D29+1 -> 27
B31: =Mufrodat!B31 -> Tinggal makan berisik betul | C31: =Mufrodat!C31 -> الْأَكْلُ فَقَطْ وَمَعَ ذَلِكَ الضَّجِيجُ كَثِيرٌ | D31: =D30+1 -> 28
B32: =Mufrodat!B32 -> Awas kepleset | C32: =Mufrodat!C32 -> اِنْتَبِهْ لَا تَنْزَلِقْ | D32: =D31+1 -> 29
B33: =Mufrodat!B33 -> Bagi yang rata | C33: =Mufrodat!C33 -> اِقْسِمْ بِالتَّسَاوِي | D33: =D32+1 -> 30
A34: 7 | B34: =Mufrodat!B34 -> Lauknya basi | C34: =Mufrodat!C34 -> الْإِدَامُ فَاسِدٌ | D34: =D33+1 -> 31
B35: =Mufrodat!B35 -> Nasinya habis | C35: =Mufrodat!C35 -> نَفِدَ الْأَرُزُّ
B36: =Mufrodat!B36 -> Centongnya tenggelam di bawah nasi | C36: =Mufrodat!C36 -> مِغْرَفَةُ الْأَرُزِّ غَارِقَةٌ تَحْتَ الْأَرُزِّ
B37: =Mufrodat!B37 -> Siapa yang nggak makan sayur? | C37: =Mufrodat!C37 -> مَنْ لَا يَأْكُلُ الْخُضَارَ؟
B38: =Mufrodat!B38 -> Nasinya belum matang | C38: =Mufrodat!C38 -> الْأَرُزُّ لَمْ يَنْضُجْ بَعْدُ
A39: 8 | B39: =Mufrodat!B39 -> Jangan lama-lama ngambil nasinya | C39: =Mufrodat!C39 -> لَا تُطِلْ فِي أَخْذِ الْأَرُزِّ
B40: =Mufrodat!B40 -> Awas licin, baru dipel | C40: =Mufrodat!C40 -> اِنْتَبِهْ، الْأَرْضُ مَبْلُولَةٌ حَدِيثًا
B41: =Mufrodat!B41 -> Sendok nasinya masuk parit | C41: =Mufrodat!C41 -> مِلْعَقَةُ الْأَرُزِّ سَقَطَتْ فِي الْمَجْرَى
...

Sheet Mufrodat Putri
A1: Mufrodat Maret - April 2026
A3: Nomor | B3: Bahasa Indonesia | C3: Bahasa Arab Putri | D3: Pagi
A4: 1 | B4: =Mufrodat!B4 -> Jangan makan pakai tangan kiri | C4: =Mufrodat!D4 -> لَا تَأْكُلِي بِيَدِكِ الْيُسْرَى | D4: 1
B5: =Mufrodat!B5 -> Kamu jahat, tidak mau bantuin aku | C5: =Mufrodat!D5 -> أَنْتِ شِرِّيرَةٌ، لَا تُرِيدِينَ أَنْ تُسَاعِدِينَنِي | D5: =D4+1 -> 2
B6: =Mufrodat!B6 -> Makan lah pakai piring | C6: =Mufrodat!D6 -> كُلِي فِي الصَّحْنِ | D6: =D5+1 -> 3
B7: =Mufrodat!B7 -> Kepalaku pusing bah | C7: =Mufrodat!D7 -> رَأْسِي يُؤْلِمُنِي | D7: =D6+1 -> 4
B8: =Mufrodat!B8 -> Cepetin bagi makanannya | C8: =Mufrodat!D8 -> أَسْرِعِي فِي تَوْزِيعِ الطَّعَامِ | D8: =D7+1 -> 5
A9: 2 | B9: =Mufrodat!B9 -> Apa lauknya? | C9: =Mufrodat!D9 -> مَا الْإِدَامُ؟ | D9: =D8+1 -> 6
B10: =Mufrodat!B10 -> Cepetin sudah ada akhwatnya / ikhwannya | C10: =Mufrodat!D10 -> أَسْرِعِي، فَقَدْ جَاءَ الْإِخْوَانُ | D10: =D9+1 -> 7
B11: =Mufrodat!B11 -> Siapa yang piket sapu? | C11: =Mufrodat!D11 -> مَنْ حَارِسَةُ الْمَطْعَمِ؟ | D11: =D10+1 -> 8
B12: =Mufrodat!B12 -> Hijabnya pindah situ | C12: =Mufrodat!D12 -> اُنْقُلِي الْحِجَابَ إِلَى هُنَاكِ | D12: =D11+1 -> 9
B13: =Mufrodat!B13 -> Ah, fresh meat | C13: =Mufrodat!D13 -> آهِ، لَحْمٌ طَازَجٌ | D13: =D12+1 -> 10
A14: 3 | B14: =Mufrodat!B14 -> Kekurangan konsumsi | C14: =Mufrodat!D14 -> الطَّعَامُ نَاقِصٌ | D14: =D13+1 -> 11
B15: =Mufrodat!B15 -> Jatahku mana? | C15: =Mufrodat!D15 -> أَيْنَ حِصَّتِي؟ | D15: =D14+1 -> 12
B16: =Mufrodat!B16 -> Makan apa? | C16: =Mufrodat!D16 -> مَاذَا نَأْكُلُ؟ | D16: =D15+1 -> 13
B17: =Mufrodat!B17 -> Ambil aja jatahku | C17: =Mufrodat!D17 -> خُذِي حِصَّتِي | D17: =D16+1 -> 14
B18: =Mufrodat!B18 -> Mana sendok nasi? | C18: =Mufrodat!D18 -> أَيْنَ مِلْعَقَةُ الْأَرُزِّ؟ | D18: =D17+1 -> 15
A19: 4 | B19: =Mufrodat!B19 -> Kamu nggak makan? | C19: =Mufrodat!D19 -> أَلَا تَأْكُلِينَ؟ | D19: =D18+1 -> 16
B20: =Mufrodat!B20 -> Siapa yang ambil makan? | C20: =Mufrodat!D20 -> مَنْ أَخَذَ الطَّعَامَ؟ | D20: =D19+1 -> 17
B21: =Mufrodat!B21 -> Makannya sudah datang | C21: =Mufrodat!D21 -> جَاءَ الطَّعَامُ | D21: =D20+1 -> 18
B22: =Mufrodat!B22 -> Siapa belum makan? | C22: =Mufrodat!D22 -> مَنْ لَمْ تَأْكُلْ؟ | D22: =D21+1 -> 19
B23: =Mufrodat!B23 -> Makan di mana? | C23: =Mufrodat!D23 -> أَيْنَ نَأْكُلُ؟ | D23: =D22+1 -> 20
A24: 5 | B24: =Mufrodat!B24 -> Tolong ambilkan ikan lele aku | C24: =Mufrodat!D24 -> مِنْ فَضْلِكِ خُذِي لِي سَمَكَ السِّلُّورِ | D24: =D23+1 -> 21
B25: =Mufrodat!B25 -> Aku mau makan | C25: =Mufrodat!D25 -> أُرِيدُ أَنْ آكُلَ | D25: =D24+1 -> 22
B26: =Mufrodat!B26 -> Siapa yang mau makananku? | C26: =Mufrodat!D26 -> مَنْ تُرِيدُ طَعَامِي؟ | D26: =D25+1 -> 23
B27: =Mufrodat!B27 -> Lantainya licin | C27: =Mufrodat!D27 -> الْأَرْضُ زَلِقَةٌ | D27: =D26+1 -> 24
B28: =Mufrodat!B28 -> Ada sambal kah? | C28: =Mufrodat!D28 -> هَلْ تُوجَدُ شَطَّةٌ؟ | D28: =D27+1 -> 25
A29: 6 | B29: =Mufrodat!B29 -> Enak betul | C29: =Mufrodat!D29 -> لَذِيذٌ جِدًّا | D29: =D28+1 -> 26
B30: =Mufrodat!B30 -> Makan kok masih hamburan | C30: =Mufrodat!D30 -> لِمَاذَا الطَّعَامُ مُتَنَاثِرٌ هَكَذَا؟ | D30: =D29+1 -> 27
B31: =Mufrodat!B31 -> Tinggal makan berisik betul | C31: =Mufrodat!D31 -> الْأَكْلُ فَقَطْ وَمَعَ ذَلِكَ الضَّجِيجُ كَثِيرٌ | D31: =D30+1 -> 28
B32: =Mufrodat!B32 -> Awas kepleset | C32: =Mufrodat!D32 -> اِنْتَبِهِي لَا تَنْزَلِقِي | D32: =D31+1 -> 29
B33: =Mufrodat!B33 -> Bagi yang rata | C33: =Mufrodat!D33 -> اِقْسِمِي بِالتَّسَاوِي | D33: =D32+1 -> 30
A34: 7 | B34: =Mufrodat!B34 -> Lauknya basi | C34: =Mufrodat!D34 -> الْإِدَامُ فَاسِدٌ | D34: =D33+1 -> 31
B35: =Mufrodat!B35 -> Nasinya habis | C35: =Mufrodat!D35 -> نَفِدَ الْأَرُزُّ
B36: =Mufrodat!B36 -> Centongnya tenggelam di bawah nasi | C36: =Mufrodat!D36 -> مِغْرَفَةُ الْأَرُزِّ غَارِقَةٌ تَحْتَ الْأَرُزِّ
B37: =Mufrodat!B37 -> Siapa yang nggak makan sayur? | C37: =Mufrodat!D37 -> مَنْ لَا تَأْكُلُ الْخُضَارَ؟
B38: =Mufrodat!B38 -> Nasinya belum matang | C38: =Mufrodat!D38 -> الْأَرُزُّ لَمْ يَنْضُجْ بَعْدُ
A39: 8 | B39: =Mufrodat!B39 -> Jangan lama-lama ngambil nasinya | C39: =Mufrodat!D39 -> لَا تُطِيلِي فِي أَخْذِ الْأَرُزِّ
B40: =Mufrodat!B40 -> Awas licin, baru dipel | C40: =Mufrodat!D40 -> اِنْتَبِهِي، الْأَرْضُ مَبْلُولَةٌ حَدِيثًا
B41: =Mufrodat!B41 -> Sendok nasinya masuk parit | C41: =Mufrodat!D41 -> مِلْعَقَةُ الْأَرُزِّ سَقَطَتْ فِي الْمَجْرَى
...

Sheet Nama Putra
A1: Nomor | B1: Nama
A2: 1 | B2: Ahmad Abdullah Kholis
A3: =A2+1 -> 2 | B3: Hanif Syaifullah
A4: =A3+1 -> 3 | B4: Ifroyim Habibullah Fatah
A5: =A4+1 -> 4 | B5: Kamil Khairul Azam
A6: =A5+1 -> 5 | B6: Mirza Faeyza Raziq Ramadhan
A7: =A6+1 -> 6 | B7: Muhammad Daffa Abdul Rafi
A8: =A7+1 -> 7 | B8: Muhammad Nizam Ghifari
A9: =A8+1 -> 8 | B9: Nadil Al Fayyadh
A10: =A9+1 -> 9 | B10: Wildan Akhram Pratama
A11: 1 | B11: Wildan Habibi Ariyadi
A12: 2 | B12: Zidane Al Asytar Syakur
A13: 3 | B13: Zufar Lahid Royyan Ashidik
A14: 4 | B14: Ibrahim Kholil Muttaqin
A15: 5 | B15: Abdullah Umar Al-Hummam
A16: 6 | B16: Afkar Mukayyis Al Wahidi
A17: 7 | B17: Ammar Azzamul Haq
A18: 8 | B18: Fatih Alfaizi Aufa Ramadhan
A19: 9 | B19: Khalid Fayyadh Al Muzzammil
A20: 1 | B20: Muhammad Alvin Abdurrahman
A21: 2 | B21: Muhammad Rizki
A22: 3 | B22: Muhammad Rizky Suhaili
... A33: 5 | B33: Umar Abdurrosyid Assary

Sheet Nama Putri
A1: Nomor | B1: Nama
A2: 1 | B2: Aiko Zahwa syarofana
A3: =A2+1 -> 2 | B3: Aisyah muwahhidah
A4: =A3+1 -> 3 | B4: Aisyah Putri Az Zahra
A5: =A4+1 -> 4 | B5: Amila nahwal Haq
A6: =A5+1 -> 5 | B6: Audrey callysta Fatih
A7: =A6+1 -> 6 | B7: Khanza nur Assyifa
A8: =A7+1 -> 7 | B8: Syifa Salsabila
A9: =A8+1 -> 8 | B9: Dhafia Ramadhiani Azzahra
A10: =A9+1 -> 9 | B10: Halwa Haura Jannaty
A11: 1 | B11: Khoirunnisa Ahlam
A12: 2 | B12: Niswah Adzkiyah
A13: 3 | B13: Sabila Farrah
A14: 4 | B14: Aina Talita Zahron
A15: 5 | B15: Aisyah Nurul Hafizah
A16: 6 | B16: Alifa Zahratun Nisa
A17: 7 | B17: Annisa Qurrotu'aini Al Adawiyah
A18: 8 | B18: Bilqis
A19: 9 | B19: Erina Liyana Zahra
A20: 1 | B20: Nur Humaira Safitri
A21: 2 | B21: Siti Sofia Azzalea
A22: 3 | B22: Zhafira Aqeela Zahra
