Workbook

Sheet Mufrodat
A1: Mufrodat Mei - Juni 2026
A3: Nomor | B3: Bahasa Indonesia | C3: Bahasa Arab Putra | D3: Bahasa Arab Putri | E3: Pagi
A4: 1 | B4: Pintu dapur lepas | C4: ٱلْبَسْ ٱلْقَلَنْسُوَةَ | D4: ٱلْبَسِي ٱلْخِمَارَ | E4: 1
B5: Pakai sudah mukenahnya (putra: songkok) | C5: هَلْ لَبِسْتَ ٱلْقَلَنْسُوَةَ؟ | D5: هَلْ لَبِسْتِ ٱلْخِمَارَ؟ | E5: =E4+1 -> 2
B6: Gayungnya kepleset weh | C6: ٱنْزَلَقَتِ ٱلْمِغْرَفَةُ | D6: ٱنْزَلَقَتِ ٱلْمِغْرَفَةُ | E6: =E5+1 -> 3
B7: Putar pang itu kipasnya | C7: أَدِرِ ٱلْمِرْوَحَةَ | D7: أَدِيرِي ٱلْمِرْوَحَةَ | E7: =E6+1 -> 4
B8: Kurang banyak | C8: قَلِيلٌ جِدًّا | D8: قَلِيلٌ جِدًّا | E8: =E7+1 -> 5
A9: 2 | B9: Maksa setoran nih | C9: يُجْبَرُ عَلَى ٱلتَّسْمِيعِ | D9: يُجْبَرُ عَلَى ٱلتَّسْمِيعِ | E9: =E8+1 -> 6
B10: Hangernya terbang | C10: طَارَتِ ٱلْعَلَّاقَةُ | D10: طَارَتِ ٱلْعَلَّاقَةُ | E10: =E9+1 -> 7
B11: Pinjam kepala cas-an nah | C11: أَعِرْنِي رَأْسَ ٱلشَّاحِنِ | D11: أَعِيرِينِي رَأْسَ ٱلشَّاحِنِ | E11: =E10+1 -> 8
B12: Woi, miring kiblatnya | C12: يَا هَذَا، ٱلْقِبْلَةُ مَائِلَةٌ | D12: يَا هَذِهِ، ٱلْقِبْلَةُ مَائِلَةٌ | E12: =E11+1 -> 9
B13: Mulutnya dijaga, jangan asbun | C13: ٱحْفَظْ فَمَكَ، لَا تَتَكَلَّمْ بِغَيْرِ عِلْمٍ | D13: ٱحْفَظِي فَمَكِ، لَا تَتَكَلَّمِي بِغَيْرِ عِلْمٍ | E13: =E12+1 -> 10
A14: 3 | B14: Jangan berenang di wastafel | C14: لَا تَسْبَحْ فِي ٱلْمِغْسَلَةِ | D14: لَا تَسْبَحِي فِي ٱلْمِغْسَلَةِ | E14: =E13+1 -> 11
B15: Eh, tolong kasur nah | C15: خُذِ ٱلْفِرَاشَ لَوْ سَمَحْتَ | D15: خُذِي ٱلْفِرَاشَ لَوْ سَمَحْتِ | E15: =E14+1 -> 12
B16: Coba lihat kalender | C16: ٱنْظُرْ إِلَى ٱلتَّقْوِيمِ | D16: ٱنْظُرِي إِلَى ٱلتَّقْوِيمِ | E16: =E15+1 -> 13
B17: Kalau malam, jangan lupa kunci jendelanya | C17: إِذَا جَاءَ ٱللَّيْلُ فَلَا تَنْسَ إِغْلَاقَ ٱلنَّافِذَةِ | D17: إِذَا جَاءَ ٱللَّيْلُ فَلَا تَنْسَيْ إِغْلَاقَ ٱلنَّافِذَةِ | E17: =E16+1 -> 14
B18: Kipasnya dicolok | C18: تَمَّ تَوْصِيلُ ٱلْمِرْوَحَةِ | D18: تَمَّ تَوْصِيلُ ٱلْمِرْوَحَةِ | E18: =E17+1 -> 15
A19: 4 | B19: Siapa hari ini piket rapiin alat tidur | C19: مَنْ ٱلْمَسْؤُولُ ٱلْيَوْمَ عَنْ تَرْتِيبِ ٱلْفُرُشِ | D19: مَنْ ٱلْمَسْؤُولَةُ ٱلْيَوْمَ عَنْ تَرْتِيبِ ٱلْفُرُشِ | E19: =E18+1 -> 16
B20: Siapa yang belum cuci botol | C20: مَنْ لَمْ يَغْسِلِ ٱلْقَارُورَةَ | D20: مَنْ لَمْ تَغْسِلِ ٱلْقَارُورَةَ | E20: =E19+1 -> 17
B21: Jangan lupa disogok airnya ke lubang | C21: لَا تَنْسَ صَبَّ ٱلْمَاءِ فِي ٱلْفُتْحَةِ | D21: لَا تَنْسَيْ صَبَّ ٱلْمَاءِ فِي ٱلْفُتْحَةِ | E21: =E20+1 -> 18
B22: Aku nggak kena kipas weh | C22: لَا يَصِلُنِي هَوَاءُ ٱلْمِرْوَحَةِ | D22: لَا يَصِلُنِي هَوَاءُ ٱلْمِرْوَحَةِ | E22: =E21+1 -> 19
B23: Ambili barang sitaanmu | C23: خُذْ أَغْرَاضَكَ ٱلْمُصَادَرَةَ | D23: خُذِي أَغْرَاضَكِ ٱلْمُصَادَرَةَ | E23: =E22+1 -> 20
A24: 5 | B24: Si paling yang mulia | C24: يَظُنُّ نَفْسَهُ أَفْضَلَ ٱلنَّاسِ | D24: تَظُنُّ نَفْسَهَا أَفْضَلَ ٱلنَّاسِ | E24: =E23+1 -> 21
B25: Jangan lupa tahajjud | C25: لَا تَنْسَ قِيَامَ ٱللَّيْلِ | D25: لَا تَنْسَيْ قِيَامَ ٱللَّيْلِ | E25: =E24+1 -> 22
B26: Kipas portable-mu ribut banget | C26: مِرْوَحَتُكَ ٱلْمَحْمُولَةُ مُزْعِجَةٌ جِدًّا | D26: مِرْوَحَتُكِ ٱلْمَحْمُولَةُ مُزْعِجَةٌ جِدًّا | E26: =E25+1 -> 23
B27: Kita belajar apa hari ini | C27: مَاذَا نَدْرُسُ ٱلْيَوْمَ | D27: مَاذَا نَدْرُسُ ٱلْيَوْمَ | E27: =E26+1 -> 24
B28: Di mana Al-Quran buat Ustadz ngajar | C28: أَيْنَ ٱلْمُصْحَفُ لِيُدَرِّسَ ٱلْأُسْتَاذُ | D28: أَيْنَ ٱلْمُصْحَفُ لِتُدَرِّسَ ٱلْأُسْتَاذَةُ | E28: =E27+1 -> 25
A29: 6 | B29: Ambilkan dulu lepek | C29: أَعْطِنِي أَوَّلًا ٱلطَّبَقَ | D29: أَعْطِينِي أَوَّلًا ٱلطَّبَقَ | E29: =E28+1 -> 26
B30: Awas gelasnya pecah | C30: ٱحْذَرْ، ٱلْكَأْسُ سَيَنْكَسِرُ | D30: ٱحْذَرِي، ٱلْكَأْسُ سَيَنْكَسِرُ | E30: =E29+1 -> 27
B31: Gulingmu dilempar | C31: وِسَادَتُكَ ٱلطَّوِيلَةُ أُلْقِيَتْ | D31: وِسَادَتُكِ ٱلطَّوِيلَةُ أُلْقِيَتْ | E31: =E30+1 -> 28
B32: Di wastafel ada kecoa | C32: فِي ٱلْمِغْسَلَةِ صُرْصُورٌ | D32: فِي ٱلْمِغْسَلَةِ صُرْصُورٌ | E32: =E31+1 -> 29
B33: Kalau makan mie, izin | C33: إِذَا أَكَلْتَ ٱلنُّودْلِزَ فَٱسْتَأْذِنْ | D33: إِذَا أَكَلْتِ ٱلنُّودْلِزَ فَٱسْتَأْذِنِي | E33: =E32+1 -> 30
A34: 7 | B34: Keranjangku terbang | C34: طَارَتْ سَلَّتِي | D34: طَارَتْ سَلَّتِي | E34: =E33+1 -> 31
B35: Sajadah siapa ini di lantai | C35: سَجَّادَةُ مَنْ هَذِهِ عَلَى ٱلْأَرْضِ | D35: سَجَّادَةُ مَنْ هَذِهِ عَلَى ٱلْأَرْضِ
B36: Siapa yang hari ini ngelanggar | C36: مَنْ خَالَفَ ٱلْيَوْمَ | D36: مَنْ خَالَفَتْ ٱلْيَوْمَ
B37: Lemarinya manis | C37: ٱلْخِزَانَةُ جَمِيلَةٌ | D37: ٱلْخِزَانَةُ جَمِيلَةٌ
B38: Tolong ambilkan gayungku nah | C38: خُذْ لِي ٱلْمِغْرَفَةَ لَوْ سَمَحْتَ | D38: خُذِي لِي ٱلْمِغْرَفَةَ لَوْ سَمَحْتِ
A39: 8 | B39: Tutup jendelanya, mau Maghrib | C39: أَغْلِقِ ٱلنَّافِذَةَ، ٱقْتَرَبَ ٱلْمَغْرِبُ | D39: أَغْلِقِي ٱلنَّافِذَةَ، ٱقْتَرَبَ ٱلْمَغْرِبُ
B40: Kasurmu mana | C40: أَيْنَ فِرَاشُكَ | D40: أَيْنَ فِرَاشُكِ
B41: Haruskah diingatin dulu | C41: هَلْ يَجِبُ أَنْ أُذَكِّرَكَ | D41: هَلْ يَجِبُ أَنْ أُذَكِّرَكِ
...

Sheet Mufrodat Putra
A1: =Mufrodat!A1 -> Mufrodat Mei - Juni 2026
A3: Nomor | B3: Bahasa Indonesia | C3: Bahasa Arab Putra | D3: Pagi
A4: 1 | B4: =Mufrodat!B4 -> Pintu dapur lepas | C4: =Mufrodat!C4 -> ٱلْبَسْ ٱلْقَلَنْسُوَةَ | D4: 1
B5: =Mufrodat!B5 -> Pakai sudah mukenahnya (putra: songkok) | C5: =Mufrodat!C5 -> هَلْ لَبِسْتَ ٱلْقَلَنْسُوَةَ؟ | D5: =D4+1 -> 2
B6: =Mufrodat!B6 -> Gayungnya kepleset weh | C6: =Mufrodat!C6 -> ٱنْزَلَقَتِ ٱلْمِغْرَفَةُ | D6: =D5+1 -> 3
B7: =Mufrodat!B7 -> Putar pang itu kipasnya | C7: =Mufrodat!C7 -> أَدِرِ ٱلْمِرْوَحَةَ | D7: =D6+1 -> 4
B8: =Mufrodat!B8 -> Kurang banyak | C8: =Mufrodat!C8 -> قَلِيلٌ جِدًّا | D8: =D7+1 -> 5
A9: 2 | B9: =Mufrodat!B9 -> Maksa setoran nih | C9: =Mufrodat!C9 -> يُجْبَرُ عَلَى ٱلتَّسْمِيعِ | D9: =D8+1 -> 6
B10: =Mufrodat!B10 -> Hangernya terbang | C10: =Mufrodat!C10 -> طَارَتِ ٱلْعَلَّاقَةُ | D10: =D9+1 -> 7
B11: =Mufrodat!B11 -> Pinjam kepala cas-an nah | C11: =Mufrodat!C11 -> أَعِرْنِي رَأْسَ ٱلشَّاحِنِ | D11: =D10+1 -> 8
B12: =Mufrodat!B12 -> Woi, miring kiblatnya | C12: =Mufrodat!C12 -> يَا هَذَا، ٱلْقِبْلَةُ مَائِلَةٌ | D12: =D11+1 -> 9
B13: =Mufrodat!B13 -> Mulutnya dijaga, jangan asbun | C13: =Mufrodat!C13 -> ٱحْفَظْ فَمَكَ، لَا تَتَكَلَّمْ بِغَيْرِ عِلْمٍ | D13: =D12+1 -> 10
A14: 3 | B14: =Mufrodat!B14 -> Jangan berenang di wastafel | C14: =Mufrodat!C14 -> لَا تَسْبَحْ فِي ٱلْمِغْسَلَةِ | D14: =D13+1 -> 11
B15: =Mufrodat!B15 -> Eh, tolong kasur nah | C15: =Mufrodat!C15 -> خُذِ ٱلْفِرَاشَ لَوْ سَمَحْتَ | D15: =D14+1 -> 12
B16: =Mufrodat!B16 -> Coba lihat kalender | C16: =Mufrodat!C16 -> ٱنْظُرْ إِلَى ٱلتَّقْوِيمِ | D16: =D15+1 -> 13
B17: =Mufrodat!B17 -> Kalau malam, jangan lupa kunci jendelanya | C17: =Mufrodat!C17 -> إِذَا جَاءَ ٱللَّيْلُ فَلَا تَنْسَ إِغْلَاقَ ٱلنَّافِذَةِ | D17: =D16+1 -> 14
B18: =Mufrodat!B18 -> Kipasnya dicolok | C18: =Mufrodat!C18 -> تَمَّ تَوْصِيلُ ٱلْمِرْوَحَةِ | D18: =D17+1 -> 15
A19: 4 | B19: =Mufrodat!B19 -> Siapa hari ini piket rapiin alat tidur | C19: =Mufrodat!C19 -> مَنْ ٱلْمَسْؤُولُ ٱلْيَوْمَ عَنْ تَرْتِيبِ ٱلْفُرُشِ | D19: =D18+1 -> 16
B20: =Mufrodat!B20 -> Siapa yang belum cuci botol | C20: =Mufrodat!C20 -> مَنْ لَمْ يَغْسِلِ ٱلْقَارُورَةَ | D20: =D19+1 -> 17
B21: =Mufrodat!B21 -> Jangan lupa disogok airnya ke lubang | C21: =Mufrodat!C21 -> لَا تَنْسَ صَبَّ ٱلْمَاءِ فِي ٱلْفُتْحَةِ | D21: =D20+1 -> 18
B22: =Mufrodat!B22 -> Aku nggak kena kipas weh | C22: =Mufrodat!C22 -> لَا يَصِلُنِي هَوَاءُ ٱلْمِرْوَحَةِ | D22: =D21+1 -> 19
B23: =Mufrodat!B23 -> Ambili barang sitaanmu | C23: =Mufrodat!C23 -> خُذْ أَغْرَاضَكَ ٱلْمُصَادَرَةَ | D23: =D22+1 -> 20
A24: 5 | B24: =Mufrodat!B24 -> Si paling yang mulia | C24: =Mufrodat!C24 -> يَظُنُّ نَفْسَهُ أَفْضَلَ ٱلنَّاسِ | D24: =D23+1 -> 21
B25: =Mufrodat!B25 -> Jangan lupa tahajjud | C25: =Mufrodat!C25 -> لَا تَنْسَ قِيَامَ ٱللَّيْلِ | D25: =D24+1 -> 22
B26: =Mufrodat!B26 -> Kipas portable-mu ribut banget | C26: =Mufrodat!C26 -> مِرْوَحَتُكَ ٱلْمَحْمُولَةُ مُزْعِجَةٌ جِدًّا | D26: =D25+1 -> 23
B27: =Mufrodat!B27 -> Kita belajar apa hari ini | C27: =Mufrodat!C27 -> مَاذَا نَدْرُسُ ٱلْيَوْمَ | D27: =D26+1 -> 24
B28: =Mufrodat!B28 -> Di mana Al-Quran buat Ustadz ngajar | C28: =Mufrodat!C28 -> أَيْنَ ٱلْمُصْحَفُ لِيُدَرِّسَ ٱلْأُسْتَاذُ | D28: =D27+1 -> 25
A29: 6 | B29: =Mufrodat!B29 -> Ambilkan dulu lepek | C29: =Mufrodat!C29 -> أَعْطِنِي أَوَّلًا ٱلطَّبَقَ | D29: =D28+1 -> 26
B30: =Mufrodat!B30 -> Awas gelasnya pecah | C30: =Mufrodat!C30 -> ٱحْذَرْ، ٱلْكَأْسُ سَيَنْكَسِرُ | D30: =D29+1 -> 27
B31: =Mufrodat!B31 -> Gulingmu dilempar | C31: =Mufrodat!C31 -> وِسَادَتُكَ ٱلطَّوِيلَةُ أُلْقِيَتْ | D31: =D30+1 -> 28
B32: =Mufrodat!B32 -> Di wastafel ada kecoa | C32: =Mufrodat!C32 -> فِي ٱلْمِغْسَلَةِ صُرْصُورٌ | D32: =D31+1 -> 29
B33: =Mufrodat!B33 -> Kalau makan mie, izin | C33: =Mufrodat!C33 -> إِذَا أَكَلْتَ ٱلنُّودْلِزَ فَٱسْتَأْذِنْ | D33: =D32+1 -> 30
A34: 7 | B34: =Mufrodat!B34 -> Keranjangku terbang | C34: =Mufrodat!C34 -> طَارَتْ سَلَّتِي | D34: =D33+1 -> 31
B35: =Mufrodat!B35 -> Sajadah siapa ini di lantai | C35: =Mufrodat!C35 -> سَجَّادَةُ مَنْ هَذِهِ عَلَى ٱلْأَرْضِ
B36: =Mufrodat!B36 -> Siapa yang hari ini ngelanggar | C36: =Mufrodat!C36 -> مَنْ خَالَفَ ٱلْيَوْمَ
B37: =Mufrodat!B37 -> Lemarinya manis | C37: =Mufrodat!C37 -> ٱلْخِزَانَةُ جَمِيلَةٌ
B38: =Mufrodat!B38 -> Tolong ambilkan gayungku nah | C38: =Mufrodat!C38 -> خُذْ لِي ٱلْمِغْرَفَةَ لَوْ سَمَحْتَ
A39: 8 | B39: =Mufrodat!B39 -> Tutup jendelanya, mau Maghrib | C39: =Mufrodat!C39 -> أَغْلِقِ ٱلنَّافِذَةَ، ٱقْتَرَبَ ٱلْمَغْرِبُ
B40: =Mufrodat!B40 -> Kasurmu mana | C40: =Mufrodat!C40 -> أَيْنَ فِرَاشُكَ
B41: =Mufrodat!B41 -> Haruskah diingatin dulu | C41: =Mufrodat!C41 -> هَلْ يَجِبُ أَنْ أُذَكِّرَكَ
...

Sheet Mufrodat Putri
A1: =Mufrodat!A1 -> Mufrodat Mei - Juni 2026
A3: Nomor | B3: Bahasa Indonesia | C3: Bahasa Arab Putri | D3: Pagi
A4: 1 | B4: =Mufrodat!B4 -> Pintu dapur lepas | C4: =Mufrodat!D4 -> ٱلْبَسِي ٱلْخِمَارَ | D4: 1
B5: =Mufrodat!B5 -> Pakai sudah mukenahnya (putra: songkok) | C5: =Mufrodat!D5 -> هَلْ لَبِسْتِ ٱلْخِمَارَ؟ | D5: =D4+1 -> 2
B6: =Mufrodat!B6 -> Gayungnya kepleset weh | C6: =Mufrodat!D6 -> ٱنْزَلَقَتِ ٱلْمِغْرَفَةُ | D6: =D5+1 -> 3
B7: =Mufrodat!B7 -> Putar pang itu kipasnya | C7: =Mufrodat!D7 -> أَدِيرِي ٱلْمِرْوَحَةَ | D7: =D6+1 -> 4
B8: =Mufrodat!B8 -> Kurang banyak | C8: =Mufrodat!D8 -> قَلِيلٌ جِدًّا | D8: =D7+1 -> 5
A9: 2 | B9: =Mufrodat!B9 -> Maksa setoran nih | C9: =Mufrodat!D9 -> يُجْبَرُ عَلَى ٱلتَّسْمِيعِ | D9: =D8+1 -> 6
B10: =Mufrodat!B10 -> Hangernya terbang | C10: =Mufrodat!D10 -> طَارَتِ ٱلْعَلَّاقَةُ | D10: =D9+1 -> 7
B11: =Mufrodat!B11 -> Pinjam kepala cas-an nah | C11: =Mufrodat!D11 -> أَعِيرِينِي رَأْسَ ٱلشَّاحِنِ | D11: =D10+1 -> 8
B12: =Mufrodat!B12 -> Woi, miring kiblatnya | C12: =Mufrodat!D12 -> يَا هَذِهِ، ٱلْقِبْلَةُ مَائِلَةٌ | D12: =D11+1 -> 9
B13: =Mufrodat!B13 -> Mulutnya dijaga, jangan asbun | C13: =Mufrodat!D13 -> ٱحْفَظِي فَمَكِ، لَا تَتَكَلَّمِي بِغَيْرِ عِلْمٍ | D13: =D12+1 -> 10
A14: 3 | B14: =Mufrodat!B14 -> Jangan berenang di wastafel | C14: =Mufrodat!D14 -> لَا تَسْبَحِي فِي ٱلْمِغْسَلَةِ | D14: =D13+1 -> 11
B15: =Mufrodat!B15 -> Eh, tolong kasur nah | C15: =Mufrodat!D15 -> خُذِي ٱلْفِرَاشَ لَوْ سَمَحْتِ | D15: =D14+1 -> 12
B16: =Mufrodat!B16 -> Coba lihat kalender | C16: =Mufrodat!D16 -> ٱنْظُرِي إِلَى ٱلتَّقْوِيمِ | D16: =D15+1 -> 13
B17: =Mufrodat!B17 -> Kalau malam, jangan lupa kunci jendelanya | C17: =Mufrodat!D17 -> إِذَا جَاءَ ٱللَّيْلُ فَلَا تَنْسَيْ إِغْلَاقَ ٱلنَّافِذَةِ | D17: =D16+1 -> 14
B18: =Mufrodat!B18 -> Kipasnya dicolok | C18: =Mufrodat!D18 -> تَمَّ تَوْصِيلُ ٱلْمِرْوَحَةِ | D18: =D17+1 -> 15
A19: 4 | B19: =Mufrodat!B19 -> Siapa hari ini piket rapiin alat tidur | C19: =Mufrodat!D19 -> مَنْ ٱلْمَسْؤُولَةُ ٱلْيَوْمَ عَنْ تَرْتِيبِ ٱلْفُرُشِ | D19: =D18+1 -> 16
B20: =Mufrodat!B20 -> Siapa yang belum cuci botol | C20: =Mufrodat!D20 -> مَنْ لَمْ تَغْسِلِ ٱلْقَارُورَةَ | D20: =D19+1 -> 17
B21: =Mufrodat!B21 -> Jangan lupa disogok airnya ke lubang | C21: =Mufrodat!D21 -> لَا تَنْسَيْ صَبَّ ٱلْمَاءِ فِي ٱلْفُتْحَةِ | D21: =D20+1 -> 18
B22: =Mufrodat!B22 -> Aku nggak kena kipas weh | C22: =Mufrodat!D22 -> لَا يَصِلُنِي هَوَاءُ ٱلْمِرْوَحَةِ | D22: =D21+1 -> 19
B23: =Mufrodat!B23 -> Ambili barang sitaanmu | C23: =Mufrodat!D23 -> خُذِي أَغْرَاضَكِ ٱلْمُصَادَرَةَ | D23: =D22+1 -> 20
A24: 5 | B24: =Mufrodat!B24 -> Si paling yang mulia | C24: =Mufrodat!D24 -> تَظُنُّ نَفْسَهَا أَفْضَلَ ٱلنَّاسِ | D24: =D23+1 -> 21
B25: =Mufrodat!B25 -> Jangan lupa tahajjud | C25: =Mufrodat!D25 -> لَا تَنْسَيْ قِيَامَ ٱللَّيْلِ | D25: =D24+1 -> 22
B26: =Mufrodat!B26 -> Kipas portable-mu ribut banget | C26: =Mufrodat!D26 -> مِرْوَحَتُكِ ٱلْمَحْمُولَةُ مُزْعِجَةٌ جِدًّا | D26: =D25+1 -> 23
B27: =Mufrodat!B27 -> Kita belajar apa hari ini | C27: =Mufrodat!D27 -> مَاذَا نَدْرُسُ ٱلْيَوْمَ | D27: =D26+1 -> 24
B28: =Mufrodat!B28 -> Di mana Al-Quran buat Ustadz ngajar | C28: =Mufrodat!D28 -> أَيْنَ ٱلْمُصْحَفُ لِتُدَرِّسَ ٱلْأُسْتَاذَةُ | D28: =D27+1 -> 25
A29: 6 | B29: =Mufrodat!B29 -> Ambilkan dulu lepek | C29: =Mufrodat!D29 -> أَعْطِينِي أَوَّلًا ٱلطَّبَقَ | D29: =D28+1 -> 26
B30: =Mufrodat!B30 -> Awas gelasnya pecah | C30: =Mufrodat!D30 -> ٱحْذَرِي، ٱلْكَأْسُ سَيَنْكَسِرُ | D30: =D29+1 -> 27
B31: =Mufrodat!B31 -> Gulingmu dilempar | C31: =Mufrodat!D31 -> وِسَادَتُكِ ٱلطَّوِيلَةُ أُلْقِيَتْ | D31: =D30+1 -> 28
B32: =Mufrodat!B32 -> Di wastafel ada kecoa | C32: =Mufrodat!D32 -> فِي ٱلْمِغْسَلَةِ صُرْصُورٌ | D32: =D31+1 -> 29
B33: =Mufrodat!B33 -> Kalau makan mie, izin | C33: =Mufrodat!D33 -> إِذَا أَكَلْتِ ٱلنُّودْلِزَ فَٱسْتَأْذِنِي | D33: =D32+1 -> 30
A34: 7 | B34: =Mufrodat!B34 -> Keranjangku terbang | C34: =Mufrodat!D34 -> طَارَتْ سَلَّتِي | D34: =D33+1 -> 31
B35: =Mufrodat!B35 -> Sajadah siapa ini di lantai | C35: =Mufrodat!D35 -> سَجَّادَةُ مَنْ هَذِهِ عَلَى ٱلْأَرْضِ
B36: =Mufrodat!B36 -> Siapa yang hari ini ngelanggar | C36: =Mufrodat!D36 -> مَنْ خَالَفَتْ ٱلْيَوْمَ
B37: =Mufrodat!B37 -> Lemarinya manis | C37: =Mufrodat!D37 -> ٱلْخِزَانَةُ جَمِيلَةٌ
B38: =Mufrodat!B38 -> Tolong ambilkan gayungku nah | C38: =Mufrodat!D38 -> خُذِي لِي ٱلْمِغْرَفَةَ لَوْ سَمَحْتِ
A39: 8 | B39: =Mufrodat!B39 -> Tutup jendelanya, mau Maghrib | C39: =Mufrodat!D39 -> أَغْلِقِي ٱلنَّافِذَةَ، ٱقْتَرَبَ ٱلْمَغْرِبُ
B40: =Mufrodat!B40 -> Kasurmu mana | C40: =Mufrodat!D40 -> أَيْنَ فِرَاشُكِ
B41: =Mufrodat!B41 -> Haruskah diingatin dulu | C41: =Mufrodat!D41 -> هَلْ يَجِبُ أَنْ أُذَكِّرَكِ
...

Sheet Nama Putra
A1: Nomor | B1: Nama
A2: 1 | B2: Ahmad Abdullah Kholis
A3: =A2+1 -> 2 | B3: Hanif Syaifullah
A4: =A3+1 -> 3 | B4: Ifroyim Habibullah Fatah
A5: =A4+1 -> 4 | B5: Kamil Khairul Azam
A6: =A5+1 -> 5 | B6: Mirza Faeyza Raziq Ramadhan
A7: =A6+1 -> 6 | B7: Muhammad Daffa Abdul Rafi
A8: =A7+1 -> 7 | B8: Muhammad Nizam Ghifari
A9: =A8+1 -> 8 | B9: Nadil Al Fayyadh
A10: =A9+1 -> 9 | B10: Wildan Akhram Pratama
A11: 1 | B11: Wildan Habibi Ariyadi
A12: 2 | B12: Zidane Al Asytar Syakur
A13: 3 | B13: Zufar Lahid Royyan Ashidik
A14: 4 | B14: Ibrahim Kholil Muttaqin
A15: 5 | B15: Abdullah Umar Al-Hummam
A16: 6 | B16: Afkar Mukayyis Al Wahidi
A17: 7 | B17: Ammar Azzamul Haq
A18: 8 | B18: Fatih Alfaizi Aufa Ramadhan
A19: 9 | B19: Khalid Fayyadh Al Muzzammil
A20: 1 | B20: Muhammad Alvin Abdurrahman
A21: 2 | B21: Muhammad Rizki
A22: 3 | B22: Muhammad Rizky Suhaili
... A33: 5 | B33: Umar Abdurrosyid Assary

Sheet Nama Putri
A1: Nomor | B1: Nama
A2: 1 | B2: Aiko Zahwa syarofana
A3: =A2+1 -> 2 | B3: Aisyah muwahhidah
A4: =A3+1 -> 3 | B4: Aisyah Putri Az Zahra
A5: =A4+1 -> 4 | B5: Amila nahwal Haq
A6: =A5+1 -> 5 | B6: Audrey callysta Fatih
A7: =A6+1 -> 6 | B7: Khanza nur Assyifa
A8: =A7+1 -> 7 | B8: Syifa Salsabila
A9: =A8+1 -> 8 | B9: Dhafia Ramadhiani Azzahra
A10: =A9+1 -> 9 | B10: Halwa Haura Jannaty
A11: 1 | B11: Khoirunnisa Ahlam
A12: 2 | B12: Niswah Adzkiyah
A13: 3 | B13: Sabila Farrah
A14: 4 | B14: Aina Talita Zahron
A15: 5 | B15: Aisyah Nurul Hafizah
A16: 6 | B16: Annisa Qurrotu'aini Al Adawiyah
A17: 7 | B17: Bilqis
A18: 8 | B18: Erina Liyana Zahra
A19: 9 | B19: Nur Humaira Safitri
A20: 1 | B20: Siti Sofia Azzalea
A21: 2 | B21: Zhafira Aqeela Zahra
